Workbook

Sheet 1st rep
A1: dest_plate | B1: dest_well | C1: gene_allele | D1: Mutation | E1: dest_well | F1: Number of cells | G1: Cytoplasm cells | H1: Cytoplasm cells with aggregates | I1: Perinuclear agg | J1: % aggregated cells | K1: % cytoplasm | L1: Notes | M1: Severity
A2: GFAP_FS_P01 | B2: B02 | C2: GFAP | D2: WT | E2: B02 | F2: 57 | G2: 20 | H2: 0 | I2: 23 | J2: 0 | K2: =G2/F2 -> 0.35087719 | L2: Not fully cytoplasmic.. IF and cytoplasm | M2: WT
A3: GFAP_FS_P01 | B3: B03 | C3: GFAP Leu76Val | D3: L76V | E3: B03 | F3: 50 | G3: 43 | H3: 29 | I3: 0 | J3: 0.58 | K3: =G3/F3 -> 0.86 | M3: INFANTILE
A4: GFAP_FS_P01 | B4: B04 | C4: GFAP Arg79Gly | D4: R79G | E4: B04 | F4: 53 | G4: 47 | H4: 41 | I4: 0 | J4: 0.77358491 | K4: =G4/F4 -> 0.88679245 | M4: INFANTILE
A5: GFAP_FS_P01 | B5: B05 | C5: GFAP Arg88Ser | D5: R88S | E5: B05 | F5: 52 | G5: 34 | H5: 19 | I5: 1 | J5: 0.36538462 | K5: =G5/F5 -> 0.65384615 | M5: INFANTILE
A6: GFAP_FS_P01 | B6: B06 | C6: GFAP Asp114Glu | D6: D114E | E6: B06 | F6: 55 | G6: 12 | H6: 0 | I6: 8 | J6: 0 | K6: =G6/F6 -> 0.21818182 | L6: Not fully cytoplasmic.. IF and cytoplasm | M6: Not in Severity list
A7: GFAP_FS_P01 | B7: B07 | C7: GFAP Arg239Cys | D7: R239C | E7: B07 | F7: 56 | G7: 53 | H7: 13 | I7: 0 | J7: 0.23214286 | K7: =G7/F7 -> 0.94642857 | M7: MOSTLY INFANTILE
A8: GFAP_FS_P01 | B8: B08 | C8: GFAP Ala253Gly | D8: A253G | E8: B08 | F8: 55 | G8: 22 | H8: 21 | I8: 2 | J8: 0.38181818 | K8: =G8/F8 -> 0.4 | M8: INFANTILE
A9: GFAP_FS_P01 | B9: B09 | C9: GFAP Glu362Asp | D9: E362D | E9: B09 | F9: 50 | G9: 35 | H9: 28 | I9: 0 | J9: 0.56 | K9: =G9/F9 -> 0.7 | M9: JUVENILE
A10: GFAP_FS_P01 | B10: B10 | C10: GFAP Arg376Trp | D10: R376W | E10: B10 | F10: 55 | G10: 21 | H10: 20 | I10: 2 | J10: 0.36363636 | K10: =G10/F10 -> 0.38181818 | M10: JUVENILE
A11: GFAP_FS_P01 | B11: C02 | C11: GFAP Lys63Gln | D11: K63Q | E11: C02 | F11: 50 | G11: 23 | H11: 18 | I11: 1 | J11: 0.36 | K11: =G11/F11 -> 0.46 | M11: ADULT
A12: GFAP_FS_P01 | B12: C03 | C12: GFAP Leu76Phe | D12: L76F | E12: C03 | F12: 60 | G12: 54 | H12: 47 | I12: 0 | J12: 0.78333333 | K12: =G12/F12 -> 0.9 | M12: INFANTILE
A13: GFAP_FS_P01 | B13: C04 | C13: GFAP Arg79Cys | D13: R79C | E13: C04 | F13: 57 | G13: 35 | H13: 49 | I13: 0 | J13: 0.85964912 | K13: =G13/F13 -> 0.61403509 | M13: MOSTLY INFANTILE
A14: GFAP_FS_P01 | B14: C05 | C14: GFAP Arg88Cys | D14: R88C | E14: C05 | F14: 53 | G14: 39 | H14: 10 | I14: 0 | J14: 0.18867925 | K14: =G14/F14 -> 0.73584906 | M14: MIXED
A15: GFAP_FS_P01 | B15: C06 | C15: GFAP Asp157Asn | D15: D157N | E15: C06 | F15: 54 | G15: 11 | H15: 0 | I15: 9 | J15: 0 | K15: =G15/F15 -> 0.2037037 | M15: INNOCUOUS
A16: GFAP_FS_P01 | B16: C07 | C16: GFAP Arg239His | D16: R239H | E16: C07 | F16: 50 | G16: 50 | H16: 23 | I16: 7 | J16: 0.46 | K16: =G16/F16 -> 1 | M16: INFANTILE
A17: GFAP_FS_P01 | B17: C08 | C17: GFAP Asp295Asn | D17: D295N | E17: C08 | F17: 57 | G17: 3 | H17: 0 | I17: 4 | J17: 0 | K17: =G17/F17 -> 0.052631579 | M17: INNOCUOUS
A18: GFAP_FS_P01 | B18: C09 | C18: GFAP Ala364Pro | D18: A364P | E18: C09 | F18: 50 | G18: 19 | H18: 17 | I18: 25 | J18: 0.34 | K18: =G18/F18 -> 0.38 | L18: weird different phenotype for perinnuclear aggregates | M18: INFANTILE
A19: GFAP_FS_P01 | B19: C10 | C19: GFAP Asn386Ile | D19: N386I | E19: C10 | F19: 66 | G19: 17 | H19: 14 | I19: 7 | J19: 0.21212121 | K19: =G19/F19 -> 0.25757576 | M19: INFANTILE
A20: GFAP_FS_P01 | B20: D02 | C20: GFAP Arg70Trp | D20: R70W | E20: D02 | F20: 52 | G20: 14 | H20: 6 | I20: 9 | J20: 0.11538462 | K20: =G20/F20 -> 0.26923077 | M20: ADULT
A21: GFAP_FS_P01 | B21: D03 | C21: GFAP Asn77Tyr | D21: N77Y | E21: D03 | F21: 53 | G21: 20 | H21: 19 | I21: 1 | J21: 0.35849057 | K21: =G21/F21 -> 0.37735849 | M21: INFANTILE
A22: GFAP_FS_P01 | B22: D05 | C22: GFAP Leu90Pro | D22: L90P | E22: D05 | F22: 50 | G22: 50 | H22: 36 | I22: 0 | J22: 0.72 | K22: =G22/F22 -> 1 | M22: INFANTILE
A23: GFAP_FS_P01 | B23: D06 | C23: GFAP Glu207Lys | D23: E207K | E23: D06 | F23: 52 | G23: 28 | H23: 0 | I23: 16 | J23: 0 | K23: =G23/F23 -> 0.53846154 | L23: perinuclear aggregation very. Large | M23: JUVENILE
A24: GFAP_FS_P01 | B24: D07 | C24: GFAP Arg239Pro | D24: R239P | E24: D07 | F24: 55 | G24: 32 | H24: 14 | I24: 1 | J24: 0.25454545 | K24: =G24/F24 -> 0.58181818 | M24: MIXED
A25: GFAP_FS_P01 | B25: D08 | C25: GFAP Leu331Pro | D25: L331P | E25: D08 | F25: 55 | G25: 8 | H25: 7 | I25: 0 | J25: 0.12727273 | K25: =G25/F25 -> 0.14545455 | L25: expression level very low | M25: INFANTILE
A26: GFAP_FS_P01 | B26: D09 | C26: GFAP Tyr366His | D26: Y366H | E26: D09 | F26: 53 | G26: 44 | H26: 21 | I26: 0 | J26: 0.39622642 | K26: =G26/F26 -> 0.83018868 | M26: INFANTILE
A27: GFAP_FS_P01 | B27: D10 | C27: GFAP Arg416Trp | D27: R416W | E27: D10 | F27: 66 | G27: 6 | H27: 6 | I27: 11 | J27: 0.090909091 | K27: =G27/F27 -> 0.090909091 | M27: MIXED
B28: D11 | C28: GFAP P47L | D28: P47L | E28: D11 | F28: 61 | G28: 9 | H28: 0 | I28: 5 | J28: 0 | K28: =G28/F28 -> 0.14754098 | M28: Not in Severity list (Benign)
A29: GFAP_FS_P01 | B29: E02 | C29: GFAP Arg70Gln | D29: R70Q | E29: E02 | F29: 51 | G29: 26 | H29: 30 | I29: 2 | J29: 0.58823529 | K29: =G29/F29 -> 0.50980392 | M29: ADULT
A30: GFAP_FS_P01 | B30: E03 | C30: GFAP Asn77Ser | D30: N77S | E30: E03 | F30: 63 | G30: 55 | H30: 22 | I30: 0 | J30: 0.34920635 | K30: =G30/F30 -> 0.87301587 | M30: INFANTILE
A31: GFAP_FS_P01 | B31: E04 | C31: GFAP Arg79Leu | D31: R79L | E31: E04 | F31: 75 | G31: 41 | H31: 28 | I31: 0 | J31: 0.37333333 | K31: =G31/F31 -> 0.54666667 | M31: INFANTILE
A32: GFAP_FS_P01 | B32: E05 | C32: GFAP Gln93Pro | D32: Q93P | E32: E05 | F32: 63 | G32: 56 | H32: 29 | I32: 0 | J32: 0.46031746 | K32: =G32/F32 -> 0.88888889 | M32: JUVENILE
A33: GFAP_FS_P01 | B33: E06 | C33: GFAP Glu210Lys | D33: E210K | E33: E06 | F33: 58 | G33: 15 | H33: 0 | I33: 14 | J33: 0 | K33: =G33/F33 -> 0.25862069 | M33: MIXED
A34: GFAP_FS_P01 | B34: E07 | C34: GFAP Arg239Leu | D34: R239L | E34: E07 | F34: 59 | G34: 56 | H34: 24 | I34: 0 | J34: 0.40677966 | K34: =G34/F34 -> 0.94915254 | M34: INFANTILE
A35: GFAP_FS_P01 | B35: E08 | C35: GFAP Leu352Pro | D35: L352P | E35: E08 | F35: 52 | G35: 16 | H35: 15 | I35: 20 | J35: 0.28846154 | K35: =G35/F35 -> 0.30769231 | M35: INFANTILE
A36: GFAP_FS_P01 | B36: E09 | C36: GFAP Glu371Gly | D36: E371G | E36: E09 | F36: 66 | G36: 54 | H36: 28 | I36: 0 | J36: 0.42424242 | K36: =G36/F36 -> 0.81818182 | M36: INFANTILE
B37: E11 | C37: GFAP R258P | D37: R258P | E37: E11 | F37: 51 | G37: 25 | H37: 12 | I37: 0 | J37: 0.23529412 | K37: =G37/F37 -> 0.49019608 | M37: INFANTILE
A38: GFAP_FS_P01 | B38: F02 | C38: GFAP Met73Thr | D38: M73T | E38: F02 | F38: 61 | G38: 59 | H38: 30 | I38: 0 | J38: 0.49180328 | K38: =G38/F38 -> 0.96721311 | M38: INFANTILE
A39: GFAP_FS_P01 | B39: F03 | C39: GFAP Asp78Glu | D39: D78E | E39: F03 | F39: 55 | G39: 9 | H39: 0 | I39: 15 | J39: 0 | K39: =G39/F39 -> 0.16363636 | L39: weird perinuclear phenotype | M39: ADULT
A40: GFAP_FS_P01 | B40: F04 | C40: GFAP Tyr83His | D40: Y83H | E40: F04 | F40: 56 | G40: 33 | H40: 15 | I40: 0 | J40: 0.26785714 | K40: =G40/F40 -> 0.58928571 | M40: INFANTILE
...

Sheet 2nd rep May 17
A1: dest_plate | B1: dest_well | C1: gene_allele | D1: Mutation | E1: dest_well | F1: Number of cells | G1: Cytoplasm only | H1: Cytoplasm cells with aggregates | I1: Presence of IF | J1: % aggregated cells | K1: % cytoplasm | L1: % IF | M1: Something | N1: % cyto corrected | O1: Severity
A2: GFAP_FS_P01 | B2: C02 | C2: GFAP Lys63Gln | D2: K63Q | E2: C02 | F2: 52 | G2: 42 | H2: 14 | I2: 31 | J2: =H2/F2 -> 0.26923077 | K2: =G2/F2 -> 0.80769231 | L2: =I2/F2 -> 0.59615385 | M2: =F2-I2 -> 21 | N2: =M2/F2 -> 0.40384615 | O2: ADULT
A3: GFAP_FS_P01 | B3: D02 | C3: GFAP Arg70Trp | D3: R70W | E3: D02 | F3: 54 | G3: 26 | H3: 3 | I3: 50 | J3: =H3/F3 -> 0.055555556 | K3: =G3/F3 -> 0.48148148 | L3: =I3/F3 -> 0.92592593 | M3: =F3-I3 -> 4 | N3: =M3/F3 -> 0.074074074 | O3: ADULT
A4: GFAP_FS_P01 | B4: E02 | C4: GFAP Arg70Gln | D4: R70Q | E4: E02 | F4: 60 | G4: 44 | H4: 32 | I4: 27 | J4: =H4/F4 -> 0.53333333 | K4: =G4/F4 -> 0.73333333 | L4: =I4/F4 -> 0.45 | M4: =F4-I4 -> 33 | N4: =M4/F4 -> 0.55 | O4: ADULT
A5: GFAP_FS_P01 | B5: F03 | C5: GFAP Asp78Glu | D5: D78E | E5: F03 | F5: 61 | G5: 43 | H5: 0 | I5: 58 | J5: =H5/F5 -> 0 | K5: =G5/F5 -> 0.70491803 | L5: =I5/F5 -> 0.95081967 | M5: =F5-I5 -> 3 | N5: =M5/F5 -> 0.049180328 | O5: ADULT
A6: GFAP_FS_P01 | B6: B03 | C6: GFAP Leu76Val | D6: L76V | E6: B03 | F6: 50 | G6: 50 | H6: 37 | I6: 5 | J6: =H6/F6 -> 0.74 | K6: =G6/F6 -> 1 | L6: =I6/F6 -> 0.1 | M6: =F6-I6 -> 45 | N6: =M6/F6 -> 0.9 | O6: INFANTILE
A7: GFAP_FS_P01 | B7: B04 | C7: GFAP Arg79Gly | D7: R79G | E7: B04 | F7: 62 | G7: 62 | H7: 54 | I7: 15 | J7: =H7/F7 -> 0.87096774 | K7: =G7/F7 -> 1 | L7: =I7/F7 -> 0.24193548 | M7: =F7-I7 -> 47 | N7: =M7/F7 -> 0.75806452 | O7: INFANTILE
A8: GFAP_FS_P01 | B8: B05 | C8: GFAP Arg88Ser | D8: R88S | E8: B05 | F8: 53 | G8: 52 | H8: 29 | I8: 7 | J8: =H8/F8 -> 0.54716981 | K8: =G8/F8 -> 0.98113208 | L8: =I8/F8 -> 0.13207547 | M8: =F8-I8 -> 46 | N8: =M8/F8 -> 0.86792453 | O8: INFANTILE
A9: GFAP_FS_P01 | B9: B08 | C9: GFAP Ala253Gly | D9: A253G | E9: B08 | F9: 80 | G9: 61 | H9: 16 | I9: 55 | J9: =H9/F9 -> 0.2 | K9: =G9/F9 -> 0.7625 | L9: =I9/F9 -> 0.6875 | M9: =F9-I9 -> 25 | N9: =M9/F9 -> 0.3125 | O9: INFANTILE
A10: GFAP_FS_P01 | B10: C03 | C10: GFAP Leu76Phe | D10: L76F | E10: C03 | F10: 69 | G10: 69 | H10: 46 | I10: 13 | J10: =H10/F10 -> 0.66666667 | K10: =G10/F10 -> 1 | L10: =I10/F10 -> 0.1884058 | M10: =F10-I10 -> 56 | N10: =M10/F10 -> 0.8115942 | O10: INFANTILE
A11: GFAP_FS_P01 | B11: C07 | C11: GFAP Arg239His | D11: R239H | E11: C07 | F11: 55 | G11: 55 | H11: 13 | I11: 21 | J11: =H11/F11 -> 0.23636364 | K11: =G11/F11 -> 1 | L11: =I11/F11 -> 0.38181818 | M11: =F11-I11 -> 34 | N11: =M11/F11 -> 0.61818182 | O11: INFANTILE
A12: GFAP_FS_P01 | B12: C09 | C12: GFAP Ala364Pro | D12: A364P | E12: C09 | F12: 52 | G12: 49 | H12: 51 | I12: 6 | J12: =H12/F12 -> 0.98076923 | K12: =G12/F12 -> 0.94230769 | L12: =I12/F12 -> 0.11538462 | M12: =F12-I12 -> 46 | N12: =M12/F12 -> 0.88461538 | O12: INFANTILE
A13: GFAP_FS_P01 | B13: C10 | C13: GFAP Asn386Ile | D13: N386I | E13: C10 | F13: 65 | G13: 57 | H13: 52 | I13: 12 | J13: =H13/F13 -> 0.8 | K13: =G13/F13 -> 0.87692308 | L13: =I13/F13 -> 0.18461538 | M13: =F13-I13 -> 53 | N13: =M13/F13 -> 0.81538462 | O13: INFANTILE
... A17: GFAP_FS_P01 | B17: D09 | C17: GFAP Tyr366His | D17: Y366H | E17: D09 | F17: 65 | G17: 64 | H17: 38 | I17: 8 | J17: =H17/F17 -> 0.58461538 | K17: =G17/F17 -> 0.98461538 | L17: =I17/F17 -> 0.12307692 | M17: =F17-I17 -> 57 | N17: =M17/F17 -> 0.87692308 | O17: INFANTILE
B18: E11 | C18: GFAP R258P | D18: R258P | E18: D11 | F18: 64 | G18: 54 | H18: 25 | I18: 32 | J18: =H18/F18 -> 0.390625 | K18: =G18/F18 -> 0.84375 | L18: =I18/F18 -> 0.5 | M18: =F18-I18 -> 32 | N18: =M18/F18 -> 0.5 | O18: INFANTILE
A19: GFAP_FS_P01 | B19: E03 | C19: GFAP Asn77Ser | D19: N77S | E19: E03 | F19: 59 | G19: 59 | H19: 16 | I19: 21 | J19: =H19/F19 -> 0.27118644 | K19: =G19/F19 -> 1 | L19: =I19/F19 -> 0.3559322 | M19: =F19-I19 -> 38 | N19: =M19/F19 -> 0.6440678 | O19: INFANTILE
A20: GFAP_FS_P01 | B20: E04 | C20: GFAP Arg79Leu | D20: R79L | E20: E04 | F20: 65 | G20: 64 | H20: 55 | I20: 4 | J20: =H20/F20 -> 0.84615385 | K20: =G20/F20 -> 0.98461538 | L20: =I20/F20 -> 0.061538462 | M20: =F20-I20 -> 61 | N20: =M20/F20 -> 0.93846154 | O20: INFANTILE
A21: GFAP_FS_P01 | B21: E07 | C21: GFAP Arg239Leu | D21: R239L | E21: E07 | F21: 53 | G21: 53 | H21: 29 | I21: 5 | J21: =H21/F21 -> 0.54716981 | K21: =G21/F21 -> 1 | L21: =I21/F21 -> 0.094339623 | M21: =F21-I21 -> 48 | N21: =M21/F21 -> 0.90566038 | O21: INFANTILE
A22: GFAP_FS_P01 | B22: E08 | C22: GFAP Leu352Pro | D22: L352P | E22: E08 | F22: 58 | G22: 53 | H22: 55 | I22: 6 | J22: =H22/F22 -> 0.94827586 | K22: =G22/F22 -> 0.9137931 | L22: =I22/F22 -> 0.10344828 | M22: =F22-I22 -> 52 | N22: =M22/F22 -> 0.89655172 | O22: INFANTILE
A23: GFAP_FS_P01 | B23: E09 | C23: GFAP Glu371Gly | D23: E371G | E23: E09 | F23: 50 | G23: 50 | H23: 48 | I23: 2 | J23: =H23/F23 -> 0.96 | K23: =G23/F23 -> 1 | L23: =I23/F23 -> 0.04 | M23: =F23-I23 -> 48 | N23: =M23/F23 -> 0.96 | O23: INFANTILE
A24: GFAP_FS_P01 | B24: F02 | C24: GFAP Met73Thr | D24: M73T | E24: F02 | F24: 64 | G24: 57 | H24: 42 | I24: 9 | J24: =H24/F24 -> 0.65625 | K24: =G24/F24 -> 0.890625 | L24: =I24/F24 -> 0.140625 | M24: =F24-I24 -> 55 | N24: =M24/F24 -> 0.859375 | O24: INFANTILE
A25: GFAP_FS_P01 | B25: F04 | C25: GFAP Tyr83His | D25: Y83H | E25: F04 | F25: 59 | G25: 59 | H25: 37 | I25: 10 | J25: =H25/F25 -> 0.62711864 | K25: =G25/F25 -> 1 | L25: =I25/F25 -> 0.16949153 | M25: =F25-I25 -> 49 | N25: =M25/F25 -> 0.83050847 | O25: INFANTILE
A26: GFAP_FS_P01 | B26: F05 | C26: GFAP Leu97Pro | D26: L97P | E26: F05 | F26: 52 | G26: 44 | H26: 30 | I26: 14 | J26: =H26/F26 -> 0.57692308 | K26: =G26/F26 -> 0.84615385 | L26: =I26/F26 -> 0.26923077 | M26: =F26-I26 -> 38 | N26: =M26/F26 -> 0.73076923 | O26: INFANTILE
A27: GFAP_FS_P01 | B27: F07 | C27: GFAP Tyr242Asp | D27: Y242D | E27: F07 | F27: 64 | G27: 63 | H27: 47 | I27: 11 | J27: =H27/F27 -> 0.734375 | K27: =G27/F27 -> 0.984375 | L27: =I27/F27 -> 0.171875 | M27: =F27-I27 -> 53 | N27: =M27/F27 -> 0.828125 | O27: INFANTILE
A28: GFAP_FS_P01 | B28: F08 | C28: GFAP Ala358Val | D28: A358V | E28: F08 | F28: 60 | G28: 49 | H28: 27 | I28: 27 | J28: =H28/F28 -> 0.45 | K28: =G28/F28 -> 0.81666667 | L28: =I28/F28 -> 0.45 | M28: =F28-I28 -> 33 | N28: =M28/F28 -> 0.55 | O28: INFANTILE
A29: GFAP_FS_P01 | B29: F09 | C29: GFAP Glu373Lys | D29: E373K | E29: F09 | F29: 60 | G29: 60 | H29: 49 | I29: 5 | J29: =H29/F29 -> 0.81666667 | K29: =G29/F29 -> 1 | L29: =I29/F29 -> 0.083333333 | M29: =F29-I29 -> 55 | N29: =M29/F29 -> 0.91666667 | O29: INFANTILE
A30: GFAP_FS_P01 | B30: G03 | C30: GFAP Arg79Ser | D30: R79S | E30: G03 | F30: 55 | G30: 54 | H30: 37 | I30: 6 | J30: =H30/F30 -> 0.67272727 | K30: =G30/F30 -> 0.98181818 | L30: =I30/F30 -> 0.10909091 | M30: =F30-I30 -> 49 | N30: =M30/F30 -> 0.89090909 | O30: INFANTILE
A31: GFAP_FS_P01 | B31: G09 | C31: GFAP Glu373Gln | D31: E373Q | E31: G09 | F31: 56 | G31: 51 | H31: 43 | I31: 13 | J31: =H31/F31 -> 0.76785714 | K31: =G31/F31 -> 0.91071429 | L31: =I31/F31 -> 0.23214286 | M31: =F31-I31 -> 43 | N31: =M31/F31 -> 0.76785714 | O31: INFANTILE
B32: G11 | C32: GFAP E374G | D32: E374G | E32: G11 | F32: 62 | G32: 62 | H32: 18 | I32: 21 | J32: =H32/F32 -> 0.29032258 | K32: =G32/F32 -> 1 | L32: =I32/F32 -> 0.33870968 | M32: =F32-I32 -> 41 | N32: =M32/F32 -> 0.66129032 | O32: INFANTILE
A33: GFAP_FS_P01 | B33: C06 | C33: GFAP Asp157Asn | D33: D157N | E33: C06 | F33: 73 | G33: 66 | H33: 3 | I33: 69 | J33: =H33/F33 -> 0.04109589 | K33: =G33/F33 -> 0.90410959 | L33: =I33/F33 -> 0.94520548 | M33: =F33-I33 -> 4 | N33: =M33/F33 -> 0.054794521 | O33: INNOCUOUS
A34: GFAP_FS_P01 | B34: C08 | C34: GFAP Asp295Asn | D34: D295N | E34: C08 | F34: 61 | G34: 33 | H34: 0 | I34: 59 | J34: =H34/F34 -> 0 | K34: =G34/F34 -> 0.54098361 | L34: =I34/F34 -> 0.96721311 | M34: =F34-I34 -> 2 | N34: =M34/F34 -> 0.032786885 | O34: INNOCUOUS
A35: GFAP_FS_P01 | B35: F06 | C35: GFAP Glu223Gln | D35: E223Q | E35: F06 | F35: 77 | G35: 20 | H35: 0 | I35: 73 | J35: =H35/F35 -> 0 | K35: =G35/F35 -> 0.25974026 | L35: =I35/F35 -> 0.94805195 | M35: =F35-I35 -> 4 | N35: =M35/F35 -> 0.051948052 | O35: INNOCUOUS
A36: GFAP_FS_P01 | B36: B09 | C36: GFAP Glu362Asp | D36: E362D | E36: B09 | F36: 56 | G36: 53 | H36: 50 | I36: 2 | J36: =H36/F36 -> 0.89285714 | K36: =G36/F36 -> 0.94642857 | L36: =I36/F36 -> 0.035714286 | M36: =F36-I36 -> 54 | N36: =M36/F36 -> 0.96428571 | O36: JUVENILE
A37: GFAP_FS_P01 | B37: B10 | C37: GFAP Arg376Trp | D37: R376W | E37: B10 | F37: 67 | G37: 60 | H37: 44 | I37: 24 | J37: =H37/F37 -> 0.65671642 | K37: =G37/F37 -> 0.89552239 | L37: =I37/F37 -> 0.35820896 | M37: =F37-I37 -> 43 | N37: =M37/F37 -> 0.64179104 | O37: JUVENILE
A38: GFAP_FS_P01 | B38: D06 | C38: GFAP Glu207Lys | D38: E207K | E38: D06 | F38: 67 | G38: 14 | H38: 2 | I38: 58 | J38: =H37/F37 -> 0.65671642 | K38: =G37/F37 -> 0.89552239 | L38: =I37/F37 -> 0.35820896 | M38: =F38-I38 -> 9 | N38: =M38/F38 -> 0.13432836 | O38: JUVENILE
A39: GFAP_FS_P01 | B39: E05 | C39: GFAP Gln93Pro | D39: Q93P | E39: E05 | F39: 62 | G39: 62 | H39: 53 | I39: 5 | J39: =H39/F39 -> 0.85483871 | K39: =G39/F39 -> 1 | L39: =I39/F39 -> 0.080645161 | M39: =F39-I39 -> 57 | N39: =M39/F39 -> 0.91935484 | O39: JUVENILE
B40: F11 | C40: GFAP E207Q | D40: E207Q | E40: F11 | F40: 55 | G40: 28 | H40: 0 | I40: 54 | J40: =H40/F40 -> 0 | K40: =G40/F40 -> 0.50909091 | L40: =I40/F40 -> 0.98181818 | M40: =F40-I40 -> 1 | N40: =M40/F40 -> 0.018181818 | O40: JUVENILE
A41: GFAP_FS_P01 | B41: G02 | C41: GFAP Met73Arg | D41: M73R | E41: G02 | F41: 58 | G41: 58 | H41: 27 | I41: 4 | J41: =H41/F41 -> 0.46551724 | K41: =G41/F41 -> 1 | L41: =I41/F41 -> 0.068965517 | M41: =F41-I41 -> 54 | N41: =M41/F41 -> 0.93103448 | O41: JUVENILE
A42: GFAP_FS_P01 | B42: G04 | C42: GFAP Val87Ile | D42: V87I | E42: G04 | F42: 61 | G42: 52 | H42: 21 | I42: 31 | J42: =H42/F42 -> 0.3442623 | K42: =G42/F42 -> 0.85245902 | L42: =I42/F42 -> 0.50819672 | M42: =F42-I42 -> 30 | N42: =M42/F42 -> 0.49180328 | O42: JUVENILE
A43: GFAP_FS_P01 | B43: G06 | C43: GFAP Leu235Pro | D43: L235P | E43: G06 | F43: 55 | G43: 50 | H43: 29 | I43: 24 | J43: =H43/F43 -> 0.52727273 | K43: =G43/F43 -> 0.90909091 | L43: =I43/F43 -> 0.43636364 | M43: =F43-I43 -> 31 | N43: =M43/F43 -> 0.56363636 | O43: JUVENILE
...

Sheet Average
A1: gene_allele | B1: Mutation | C1: dest_well | D1: Severity | E1: Updated severity | F1: Type | G1: AlphaMissense score | H1: AlphaMissense class | I1: Average age of onset | J1: Aggregates R1 | K1: Aggregates R2 | L1: Cytoplasm R1 | M1: Cytoplasm R1 corrected | N1: Cytoplasm R2 | O1: IF R1 | P1: Aggregates avg | Q1: Cytoplasm Avg | R1: Cytoplasm Avg rep1 corrected | S1: IS 1 | T1: IS 2 | U1: IS average
A2: GFAP Lys63Gln | B2: K63Q | C2: C02 | D2: Adult | E2: Adult | G2: 0.1816 | H2: benign | I2: 21 | J2: 0.26923077 | K2: 0.36 | L2: 0.80769231 | M2: 0.40384615 | N2: 0.46 | O2: 0.59615385 | P2: =AVERAGE(J2:K2) -> 0.31461538 | Q2: =AVERAGE(L2:M2) -> 0.60576923 | R2: =AVERAGE(M2:N2) -> 0.43192308 | S2: 0.56292114 | T2: 0.58454255 | U2: 0.57373184
A3: GFAP Arg70Trp | B3: R70W | C3: D02 | D3: Adult | E3: Adult | F3: bulbospinal | G3: 0.8274 | H3: pathogenic | J3: 0.055555556 | K3: 0.11538462 | L3: 0.48148148 | M3: 0.074074074 | N3: 0.26923077 | O3: 0.92592593 | P3: =AVERAGE(J3:K3) -> 0.085470085 | Q3: =AVERAGE(L3:M3) -> 0.27777778 | R3: =AVERAGE(M3:N3) -> 0.17165242 | S3: 0.42676012 | T3: 0.14587951 | U3: 0.28631982
A4: GFAP Arg70Gln | B4: R70Q | C4: E02 | D4: Adult | E4: Adult | G4: 0.367 | H4: ambiguous | I4: 40.5 | J4: 0.53333333 | K4: 0.58823529 | L4: 0.73333333 | M4: 0.55 | N4: 0.50980392 | O4: 0.45 | P4: =AVERAGE(J4:K4) -> 0.56078431 | Q4: =AVERAGE(L4:M4) -> 0.64166667 | R4: =AVERAGE(M4:N4) -> 0.52990196 | S4: 0.5268519 | T4: 0.45628892 | U4: 0.49157041
A5: GFAP Asp78Glu | B5: D78E | C5: F03 | D5: Adult | E5: Adult | G5: 0.9071 | H5: pathogenic | J5: 0 | K5: 0 | L5: 0.70491803 | M5: 0.049180328 | N5: 0.16363636 | O5: 0.95081967 | P5: =AVERAGE(J5:K5) -> 0 | Q5: =AVERAGE(L5:M5) -> 0.37704918 | R5: =AVERAGE(M5:N5) -> 0.10640835 | S5: 0.46787485 | T5: 0.17225621 | U5: 0.32006553
A6: GFAP Glu210Lys | B6: E210K | C6: E06 | D6: Mixed | E6: Adult | F6: bulbospinal | G6: 0.5754 | H6: pathogenic | I6: 24 | J6: 0 | K6: 0 | L6: 1 | M6: 0.08 | N6: 0.25862069 | O6: 0.92 | P6: =AVERAGE(J6:K6) -> 0 | Q6: =AVERAGE(L6:M6) -> 0.54 | R6: =AVERAGE(M6:N6) -> 0.16931034 | S6: 0.46523341 | T6: 0.51861264 | U6: 0.49192303
A7: GFAP P47L | B7: P47L | C7: E11 | D7: benign | E7: benign | G7: 0.1464 | H7: benign | J7: 0 | K7: 0 | L7: 0.48275862 | M7: 0 | N7: 0.14754098 | O7: 1 | P7: =AVERAGE(J7:K7) -> 0 | Q7: =AVERAGE(L7:M7) -> 0.24137931 | R7: =AVERAGE(M7:N7) -> 0.073770492 | S7: 0.5910532 | T7: 0.091285817 | U7: 0.34116951
A8: GFAP Asp157Asn | B8: D157N | C8: C06 | D8: benign/likely benign | E8: benign/likely benign | G8: 0.1403 | H8: benign | J8: 0.04109589 | K8: 0 | L8: 0.90410959 | M8: 0.054794521 | N8: 0.2037037 | O8: 0.94520548 | P8: =AVERAGE(J8:K8) -> 0.020547945 | Q8: =AVERAGE(L8:M8) -> 0.47945205 | R8: =AVERAGE(M8:N8) -> 0.12924911 | S8: 0.28644133 | T8: 0.43540294 | U8: 0.36092213
A9: GFAP Asp295Asn | B9: D295N | C9: C08 | D9: benign/likely benign | E9: benign/likely benign | G9: 0.3429 | H9: ambiguous | J9: 0 | K9: 0 | L9: 0.54098361 | M9: 0.032786885 | N9: 0.052631579 | O9: 0.96721311 | P9: =AVERAGE(J9:K9) -> 0 | Q9: =AVERAGE(L9:M9) -> 0.28688525 | R9: =AVERAGE(M9:N9) -> 0.042709232 | S9: 0.19098544 | T9: 0.15516902 | U9: 0.17307723
A10: GFAP Glu223Gln | B10: E223Q | C10: F06 | D10: benign/likely benign | E10: benign/likely benign | G10: 0.1902 | H10: benign | J10: 0 | K10: 0 | L10: 0.25974026 | M10: 0.051948052 | N10: 0 | O10: 0.94805195 | P10: =AVERAGE(J10:K10) -> 0 | Q10: =AVERAGE(L10:M10) -> 0.15584416 | R10: =AVERAGE(M10:N10) -> 0.025974026 | S10: 0.28628247 | T10: 0.51530208 | U10: 0.40079227
A11: GFAP Asp114Glu | B11: D114E | C11: B06 | D11: benign/likely benign | E11: benign/likely benign | G11: 0.1726 | H11: benign | J11: 0.10526316 | K11: 0 | L11: 0.48684211 | M11: 0.092105263 | N11: 0.21818182 | O11: 0.90789474 | P11: =AVERAGE(J11:K11) -> 0.052631579 | Q11: =AVERAGE(L11:M11) -> 0.28947368 | R11: =AVERAGE(M11:N11) -> 0.15514354 | S11: 0.43976892 | T11: 0.60397014 | U11: 0.52186953
A12: GFAP Arg105Trp | B12: R105W | C12: G05 | D12: benign/likely benign | E12: benign/likely benign | G12: 0.2892 | H12: benign | J12: 0.037735849 | K12: 0 | L12: 0.9245283 | M12: 0.075471698 | N12: 0.098039216 | O12: 0.9245283 | P12: =AVERAGE(J12:K12) -> 0.018867925 | Q12: =AVERAGE(L12:M12) -> 0.5 | R12: =AVERAGE(M12:N12) -> 0.086755457 | S12: 0.26485175 | T12: 0.52733862 | U12: 0.39609518
A13: GFAP Leu76Val | B13: L76V | C13: B03 | D13: Infantile | E13: Infantile | G13: 0.9414 | H13: pathogenic | I13: 0.41666667 | J13: 0.74 | K13: 0.58 | L13: 1 | M13: 0.9 | N13: 0.86 | O13: 0.1 | P13: =AVERAGE(J13:K13) -> 0.66 | Q13: =AVERAGE(L13:M13) -> 0.95 | R13: =AVERAGE(M13:N13) -> 0.88 | S13: 0.53513379 | T13: 0.71754601 | U13: 0.6263399
A14: GFAP Arg79Gly | B14: R79G | C14: B04 | D14: Infantile | E14: Infantile | G14: 0.975 | H14: pathogenic | J14: 0.87096774 | K14: 0.77358491 | L14: 1 | M14: 0.75806452 | N14: 0.88679245 | O14: 0.24193548 | P14: =AVERAGE(J14:K14) -> 0.82227632 | Q14: =AVERAGE(L14:M14) -> 0.87903226 | R14: =AVERAGE(M14:N14) -> 0.82242848 | S14: 0.50892946 | T14: 0.5568921 | U14: 0.53291078
A15: GFAP Arg88Ser | B15: R88S | C15: B05 | D15: Infantile | E15: Infantile | G15: 0.9672 | H15: pathogenic | J15: 0.54716981 | K15: 0.36538462 | L15: 0.98113208 | M15: 0.86792453 | N15: 0.65384615 | O15: 0.13207547 | P15: =AVERAGE(J15:K15) -> 0.45627721 | Q15: =AVERAGE(L15:M15) -> 0.9245283 | R15: =AVERAGE(M15:N15) -> 0.76088534 | S15: 0.5129175 | T15: 0.66521855 | U15: 0.58906803
A16: GFAP Ala253Gly | B16: A253G | C16: B08 | D16: Infantile | E16: Infantile | G16: 0.3904 | H16: ambiguous | I16: 1 | J16: 0.2 | K16: 0.38181818 | L16: 0.7625 | M16: 0.3125 | N16: 0.4 | O16: 0.6875 | P16: =AVERAGE(J16:K16) -> 0.29090909 | Q16: =AVERAGE(L16:M16) -> 0.5375 | R16: =AVERAGE(M16:N16) -> 0.35625 | S16: 0.44530595 | T16: 0.27346314 | U16: 0.35938454
A17: GFAP Leu76Phe | B17: L76F | C17: C03 | D17: Infantile | E17: Infantile | G17: 0.9934 | H17: pathogenic | J17: 0.66666667 | K17: 0.78333333 | L17: 1 | M17: 0.8115942 | N17: 0.9 | O17: 0.1884058 | P17: =AVERAGE(J17:K17) -> 0.725 | Q17: =AVERAGE(L17:M17) -> 0.9057971 | R17: =AVERAGE(M17:N17) -> 0.8557971 | S17: 0.58207404 | T17: 0.68158223 | U17: 0.63182813
A18: GFAP Arg239His | B18: R239H | C18: C07 | D18: Infantile | E18: Infantile | G18: 0.5695 | H18: pathogenic | J18: 0.23636364 | K18: 0.46 | L18: 1 | M18: 0.61818182 | N18: 1 | O18: 0.38181818 | P18: =AVERAGE(J18:K18) -> 0.34818182 | Q18: =AVERAGE(L18:M18) -> 0.80909091 | R18: =AVERAGE(M18:N18) -> 0.80909091 | S18: 0.58118657 | T18: 0.60628508 | U18: 0.59373582
A19: GFAP Ala364Pro | B19: A364P | C19: C09 | D19: Infantile | E19: Infantile | G19: 0.9981 | H19: pathogenic | I19: 0 | J19: 0.98076923 | K19: 0.34 | L19: 0.94230769 | M19: 0.88461538 | N19: 0.38 | O19: 0.11538462 | P19: =AVERAGE(J19:K19) -> 0.66038462 | Q19: =AVERAGE(L19:M19) -> 0.91346154 | R19: =AVERAGE(M19:N19) -> 0.63230769 | S19: 0.47814726 | T19: 0.3403378 | U19: 0.40924253
A20: GFAP Asn386Ile | B20: N386I | C20: C10 | D20: Infantile | E20: Infantile | G20: 0.5294 | H20: ambiguous | J20: 0.8 | K20: 0.21212121 | L20: 0.87692308 | M20: 0.81538462 | N20: 0.25757576 | O20: 0.18461538 | P20: =AVERAGE(J20:K20) -> 0.50606061 | Q20: =AVERAGE(L20:M20) -> 0.84615385 | R20: =AVERAGE(M20:N20) -> 0.53648019 | S20: 0.35705445 | T20: 0.40255037 | U20: 0.37980241
A21: GFAP Asn77Tyr | B21: N77Y | C21: D03 | D21: Infantile | E21: Infantile | G21: 0.9897 | H21: pathogenic | J21: 0.91071429 | K21: 0.35849057 | L21: 0.98214286 | M21: 0.91071429 | N21: 0.37735849 | O21: 0.089285714 | P21: =AVERAGE(J21:K21) -> 0.63460243 | Q21: =AVERAGE(L21:M21) -> 0.94642857 | R21: =AVERAGE(M21:N21) -> 0.64403639 | S21: 0.63582352 | T21: 0.51984663 | U21: 0.57783507
A22: GFAP Leu90Pro | B22: L90P | C22: D05 | D22: Infantile | E22: Infantile | G22: 0.9976 | H22: pathogenic | J22: 0.85507246 | K22: 0.72 | L22: 1 | M22: 0.91304348 | N22: 1 | O22: 0.089285714 | P22: =AVERAGE(J22:K22) -> 0.78753623 | Q22: =AVERAGE(L22:M22) -> 0.95652174 | R22: =AVERAGE(M22:N22) -> 0.95652174 | S22: 0.40917172 | T22: 0.70735026 | U22: 0.55826099
A23: GFAP Leu331Pro | B23: L331P | C23: D08 | D23: Infantile | E23: Infantile | G23: 0.9744 | H23: pathogenic | J23: 0.43055556 | K23: 0.12727273 | L23: 0.69444444 | M23: 0.44444444 | N23: 0.14545455 | O23: 0.55555556 | P23: =AVERAGE(J23:K23) -> 0.27891414 | Q23: =AVERAGE(L23:M23) -> 0.56944444 | R23: =AVERAGE(M23:N23) -> 0.29494949 | S23: 0.65774243 | T23: 0.21242228 | U23: 0.43508235
A24: GFAP Tyr366His | B24: Y366H | C24: D09 | D24: Infantile | E24: Infantile | G24: 0.9983 | H24: pathogenic | I24: 0.083333333 | J24: 0.58461538 | K24: 0.39622642 | L24: 0.98461538 | M24: 0.87692308 | N24: 0.83018868 | O24: 0.12307692 | P24: =AVERAGE(J24:K24) -> 0.4904209 | Q24: =AVERAGE(L24:M24) -> 0.93076923 | R24: =AVERAGE(M24:N24) -> 0.85355588 | S24: 0.68691507 | T24: 0.49341588 | U24: 0.59016547
A25: GFAP R258P | B25: R258P | C25: D11 | D25: Infantile | E25: Infantile | G25: 0.9485 | H25: pathogenic | J25: 0.390625 | K25: 0.23529412 | L25: 0.84375 | M25: 0.5 | N25: 0.49019608 | O25: 0.5 | P25: =AVERAGE(J25:K25) -> 0.31295956 | Q25: =AVERAGE(L25:M25) -> 0.671875 | R25: =AVERAGE(M25:N25) -> 0.49509804 | S25: 0.71020478 | T25: 0.39976942 | U25: 0.5549871
A26: GFAP Asn77Ser | B26: N77S | C26: E03 | D26: Infantile | E26: Infantile | G26: 0.9648 | H26: pathogenic | I26: 0.58333333 | J26: 0.27118644 | K26: 0.34920635 | L26: 1 | M26: 0.6440678 | N26: 0.87301587 | O26: 0.3559322 | P26: =AVERAGE(J26:K26) -> 0.31019639 | Q26: =AVERAGE(L26:M26) -> 0.8220339 | R26: =AVERAGE(M26:N26) -> 0.75854183 | S26: 0.59670125 | T26: 0.46240051 | U26: 0.52955088
A27: GFAP Arg79Leu | B27: R79L | C27: E04 | D27: Infantile | E27: Infantile | G27: 0.9364 | H27: pathogenic | J27: 0.84615385 | K27: 0.37333333 | L27: 0.98461538 | M27: 0.93846154 | N27: 0.54666667 | O27: 0.061538462 | P27: =AVERAGE(J27:K27) -> 0.60974359 | Q27: =AVERAGE(L27:M27) -> 0.96153846 | R27: =AVERAGE(M27:N27) -> 0.7425641 | S27: 0.75736518 | T27: 0.72170222 | U27: 0.7395337
A28: GFAP Arg239Leu | B28: R239L | C28: E07 | D28: Infantile | E28: Infantile | G28: 0.9505 | H28: pathogenic | J28: 0.54716981 | K28: 0.40677966 | L28: 1 | M28: 0.90566038 | N28: 0.94915254 | O28: 0.094339623 | P28: =AVERAGE(J28:K28) -> 0.47697474 | Q28: =AVERAGE(L28:M28) -> 0.95283019 | R28: =AVERAGE(M28:N28) -> 0.92740646 | S28: 0.58251286 | T28: 0.77282214 | U28: 0.6776675
A29: GFAP Leu352Pro | B29: L352P | C29: E08 | D29: Infantile | E29: Infantile | G29: 0.9992 | H29: pathogenic | J29: 0.94827586 | K29: 0.28846154 | L29: 0.9137931 | M29: 0.89655172 | N29: 0.30769231 | O29: 0.10344828 | P29: =AVERAGE(J29:K29) -> 0.6183687 | Q29: =AVERAGE(L29:M29) -> 0.90517241 | R29: =AVERAGE(M29:N29) -> 0.60212202 | S29: 0.48076755 | T29: 0.23764646 | U29: 0.35920701
A30: GFAP Glu371Gly | B30: E371G | C30: E09 | D30: Infantile | E30: Infantile | G30: 0.9066 | H30: pathogenic | J30: 0.96 | K30: 0.42424242 | L30: 1 | M30: 0.96 | N30: 0.81818182 | O30: 0.04 | P30: =AVERAGE(J30:K30) -> 0.69212121 | Q30: =AVERAGE(L30:M30) -> 0.98 | R30: =AVERAGE(M30:N30) -> 0.88909091 | S30: 0.82906295 | T30: 0.64404901 | U30: 0.73655598
A31: GFAP Met73Thr | B31: M73T | C31: F02 | D31: Infantile | E31: Infantile | G31: 0.9945 | H31: pathogenic | I31: 0.25 | J31: 0.65625 | K31: 0.49180328 | L31: 0.890625 | M31: 0.859375 | N31: 0.96721311 | O31: 0.140625 | P31: =AVERAGE(J31:K31) -> 0.57402664 | Q31: =AVERAGE(L31:M31) -> 0.875 | R31: =AVERAGE(M31:N31) -> 0.91329406 | S31: 0.64265996 | T31: 0.68769635 | U31: 0.66517816
A32: GFAP Tyr83His | B32: Y83H | C32: F04 | D32: Infantile | E32: Infantile | G32: 0.9819 | H32: pathogenic | J32: 0.62711864 | K32: 0.26785714 | L32: 1 | M32: 0.83050847 | N32: 0.58928571 | O32: 0.16949153 | P32: =AVERAGE(J32:K32) -> 0.44748789 | Q32: =AVERAGE(L32:M32) -> 0.91525424 | R32: =AVERAGE(M32:N32) -> 0.70989709 | S32: 0.68740022 | T32: 0.73185646 | U32: 0.70962834
A33: GFAP Leu97Pro | B33: L97P | C33: F05 | D33: Infantile | E33: Infantile | G33: 0.9895 | H33: pathogenic | J33: 0.57692308 | L33: 0.84615385 | M33: 0.73076923 | O33: 0.26923077 | S33: 0.60886768 | T33: 0.63923661 | U33: 0.62405214
A34: GFAP Tyr242Asp | B34: Y242D | C34: F07 | D34: Infantile | E34: Infantile | G34: 0.9729 | H34: pathogenic | J34: 0.734375 | K34: 0.61818182 | L34: 0.984375 | M34: 0.828125 | N34: 0.92727273 | O34: 0.171875 | P34: =AVERAGE(J34:K34) -> 0.67627841 | Q34: =AVERAGE(L34:M34) -> 0.90625 | R34: =AVERAGE(M34:N34) -> 0.87769886 | S34: 0.73386045 | T34: 0.42482877 | U34: 0.57934461
A35: GFAP Ala358Val | B35: A358V | C35: F08 | D35: Infantile | E35: Infantile | G35: 0.91 | H35: pathogenic | J35: 0.45 | K35: 0.098039216 | L35: 0.81666667 | M35: 0.55 | N35: 0.15686275 | O35: 0.45 | P35: =AVERAGE(J35:K35) -> 0.27401961 | Q35: =AVERAGE(L35:M35) -> 0.68333333 | R35: =AVERAGE(M35:N35) -> 0.35343137 | S35: 0.3434535 | T35: 0.39814811 | U35: 0.37080081
A36: GFAP Glu373Lys | B36: E373K | C36: F09 | D36: Infantile | E36: Infantile | G36: 0.9671 | H36: pathogenic | J36: 0.81666667 | K36: 0.33333333 | L36: 1 | M36: 0.91666667 | N36: 1 | O36: 0.083333333 | P36: =AVERAGE(J36:K36) -> 0.575 | Q36: =AVERAGE(L36:M36) -> 0.95833333 | R36: =AVERAGE(M36:N36) -> 0.95833333 | S36: 0.73961091 | T36: 0.72753631 | U36: 0.73357361
A37: GFAP Arg79Ser | B37: R79S | C37: G03 | D37: Infantile | E37: Infantile | G37: 0.9849 | H37: pathogenic | J37: 0.67272727 | K37: 0.6779661 | L37: 0.98181818 | M37: 0.89090909 | N37: 0.88135593 | O37: 0.10909091 | P37: =AVERAGE(J37:K37) -> 0.67534669 | Q37: =AVERAGE(L37:M37) -> 0.93636364 | R37: =AVERAGE(M37:N37) -> 0.88613251 | S37: 0.7843921 | T37: 0.70378475 | U37: 0.74408843
A38: GFAP Glu373Gln | B38: E373Q | C38: G09 | D38: Infantile | E38: Infantile | G38: 0.94 | H38: pathogenic | I38: 0.25 | J38: 0.76785714 | K38: 0.27777778 | L38: 0.91071429 | M38: 0.76785714 | N38: 0.59259259 | O38: 0.23214286 | P38: =AVERAGE(J38:K38) -> 0.52281746 | Q38: =AVERAGE(L38:M38) -> 0.83928571 | R38: =AVERAGE(M38:N38) -> 0.68022487 | S38: 0.70229593 | T38: 0.64113224 | U38: 0.67171409
A39: GFAP E374G | B39: E374G | C39: G11 | D39: Infantile | E39: Infantile | G39: 0.8911 | H39: pathogenic | I39: 0.75 | J39: 0.29032258 | K39: 0.46666667 | L39: 1 | M39: 0.66129032 | N39: 1 | O39: 0.33870968 | P39: =AVERAGE(J39:K39) -> 0.37849462 | Q39: =AVERAGE(L39:M39) -> 0.83064516 | R39: =AVERAGE(M39:N39) -> 0.83064516 | S39: 0.68560972 | T39: 0.35600985 | U39: 0.52080978
A40: GFAP Arg239Pro | B40: R239P | C40: D07 | D40: Mixed | E40: Infantile | G40: 0.9951 | H40: pathogenic | J40: 0.7254902 | K40: 0.25454545 | L40: 0.96078431 | M40: 0.76470588 | N40: 0.58181818 | O40: 0.23529412 | P40: =AVERAGE(J40:K40) -> 0.49001783 | Q40: =AVERAGE(L40:M40) -> 0.8627451 | R40: =AVERAGE(M40:N40) -> 0.67326203 | S40: 0.793953 | T40: 0.62718186 | U40: 0.71056743
...

Sheet Location annotations
M1: Rep 1 annotations | R1: Rep 2 Annotations
A2: dest_well | B2: gene_allele | C2: Mutation | D2: dest_well | E2: Number of cells | F2: Cytoplasm cells | G2: Cytoplasm cells with aggregates | H2: Perinuclear agg | I2: % aggregated cells | J2: % cytoplasm | K2: Notes | L2: Severity | M2: Localization | N2: Transfection Efficiency | O2: Hit? | P2: Foci? | Q2: Notes | R2: Localization | S2: Transfection Efficiency | T2: Hit? | U2: Foci? | V2: Notes | W2: Replicates match? | X2: Severity
A3: B02 | B3: GFAP | C3: WT | D3: B02 | E3: 57 | F3: 20 | G3: 0 | H3: 23 | I3: =G3/E3 -> 0 | J3: =F3/E3 -> 0.35087719 | K3: Not fully cytoplasmic.. IF and cytoplasm | L3: WT | M3: IF | N3: High | R3: IF | S3: High | X3: #N/A
A4: B03 | B4: GFAP Leu76Val | C4: L76V | D4: B03 | E4: 50 | F4: 43 | G4: 29 | H4: 0 | I4: =G4/E4 -> 0.58 | J4: =F4/E4 -> 0.86 | L4: INFANTILE | M4: Cytoplasm | N4: Med | O4: Y | P4: Foci | R4: Cytoplasm | S4: High | T4: Y | U4: Foci | W4: =IF(O4=T4, TRUE) -> TRUE | X4: INFANTILE
A5: B04 | B5: GFAP Arg79Gly | C5: R79G | D5: B04 | E5: 53 | F5: 47 | G5: 41 | H5: 0 | I5: =G5/E5 -> 0.77358491 | J5: =F5/E5 -> 0.88679245 | L5: INFANTILE | M5: Not expressed | N5: NE | O5: NE | R5: Cytoplasm | S5: High | T5: Y | U5: Foci | X5: INFANTILE
A6: B05 | B6: GFAP Arg88Ser | C6: R88S | D6: B05 | E6: 52 | F6: 34 | G6: 19 | H6: 1 | I6: =G6/E6 -> 0.36538462 | J6: =F6/E6 -> 0.65384615 | L6: INFANTILE | M6: Cytoplasm | N6: Low | O6: Y | P6: Foci | R6: Cytoplasm | S6: High | T6: Y | U6: Foci | W6: =IF(O6=T6, TRUE) -> TRUE | X6: INFANTILE
A7: B06 | B7: GFAP Asp114Glu | C7: D114E | D7: B06 | E7: 55 | F7: 12 | G7: 0 | H7: 8 | I7: =G7/E7 -> 0 | J7: =F7/E7 -> 0.21818182 | K7: Not fully cytoplasmic.. IF and cytoplasm | L7: Not in Severity list | M7: IF | N7: Med | O7: N | R7: IF | S7: Med | T7: N | W7: =IF(O7=T7, TRUE) -> TRUE | X7: Not in Severity list
A8: B07 | B8: GFAP Arg239Cys | C8: R239C | D8: B07 | E8: 56 | F8: 53 | G8: 13 | H8: 0 | I8: =G8/E8 -> 0.23214286 | J8: =F8/E8 -> 0.94642857 | L8: MOSTLY INFANTILE | M8: Cytoplasm | N8: Med | O8: Y | P8: Foci | R8: Cytoplasm | S8: Med | T8: Y | U8: Foci | W8: =IF(O8=T8, TRUE) -> TRUE | X8: MOSTLY INFANTILE
A9: B08 | B9: GFAP Ala253Gly | C9: A253G | D9: B08 | E9: 55 | F9: 22 | G9: 21 | H9: 2 | I9: =G9/E9 -> 0.38181818 | J9: =F9/E9 -> 0.4 | L9: INFANTILE | M9: Not Expressed | N9: NE | O9: NE | R9: Cytoplasm, IF | S9: High | T9: Y | U9: Foci | X9: INFANTILE
A10: B09 | B10: GFAP Glu362Asp | C10: E362D | D10: B09 | E10: 50 | F10: 35 | G10: 28 | H10: 0 | I10: =G10/E10 -> 0.56 | J10: =F10/E10 -> 0.7 | L10: JUVENILE | M10: Not expressed | N10: NE | O10: NE | R10: Cytoplasm | S10: High | T10: Y | U10: Foci | X10: JUVENILE
A11: B10 | B11: GFAP Arg376Trp | C11: R376W | D11: B10 | E11: 55 | F11: 21 | G11: 20 | H11: 2 | I11: =G11/E11 -> 0.36363636 | J11: =F11/E11 -> 0.38181818 | L11: JUVENILE | M11: IF | N11: High | O11: Y | P11: Foci | R11: Cytoplasm, IF | S11: High | T11: Y | U11: Foci | W11: =IF(O11=T11, TRUE) -> TRUE | X11: JUVENILE
A12: B11 | B12: GFAP R239H | C12: R239H | D12: B11 | L12: INFANTILE | M12: Not expressed | N12: NE | O12: NE | Q12: Not enough cells to tell | R12: Not expressed | S12: NE | T12: NE | X12: INFANTILE
A13: C02 | B13: GFAP Lys63Gln | C13: K63Q | D13: C02 | E13: 50 | F13: 23 | G13: 18 | H13: 1 | I13: =G13/E13 -> 0.36 | J13: =F13/E13 -> 0.46 | L13: ADULT | M13: IF | N13: Low | O13: Y | P13: Some cells with Foci | Q13: Few cells overall | R13: IF, Cytoplasm | S13: High | T13: Y | U13: Foci | W13: =IF(O13=T13, TRUE) -> TRUE | X13: ADULT
A14: C03 | B14: GFAP Leu76Phe | C14: L76F | D14: C03 | E14: 60 | F14: 54 | G14: 47 | H14: 0 | I14: =G14/E14 -> 0.78333333 | J14: =F14/E14 -> 0.9 | L14: INFANTILE | M14: Cytoplasm | N14: Med | O14: Y | P14: Foci | R14: Cytoplasm | S14: High | T14: Y | U14: Foci | W14: =IF(O14=T14, TRUE) -> TRUE | X14: INFANTILE
A15: C04 | B15: GFAP Arg79Cys | C15: R79C | D15: C04 | E15: 57 | F15: 35 | G15: 49 | H15: 0 | I15: =G15/E15 -> 0.85964912 | J15: =F15/E15 -> 0.61403509 | L15: MOSTLY INFANTILE | M15: Cytoplasm | N15: Low | O15: Y | P15: Foci, 5 cells | R15: Cytoplasm | S15: High | T15: Y | U15: Foci | W15: =IF(O15=T15, TRUE) -> TRUE | X15: MOSTLY INFANTILE
A16: C05 | B16: GFAP Arg88Cys | C16: R88C | D16: C05 | E16: 53 | F16: 39 | G16: 10 | H16: 0 | I16: =G16/E16 -> 0.18867925 | J16: =F16/E16 -> 0.73584906 | L16: MIXED | M16: Cytoplasm, IF | N16: Low | O16: Y | R16: Cytoplasm, IF | S16: High | T16: Y | U16: Foci | W16: =IF(O16=T16, TRUE) -> TRUE | X16: MIXED
A17: C06 | B17: GFAP Asp157Asn | C17: D157N | D17: C06 | E17: 54 | F17: 11 | G17: 0 | H17: 9 | I17: =G17/E17 -> 0 | J17: =F17/E17 -> 0.2037037 | L17: INNOCUOUS | M17: IF | N17: Low | O17: N | R17: IF | S17: High | T17: N | W17: =IF(O17=T17, TRUE) -> TRUE | X17: INNOCUOUS
A18: C07 | B18: GFAP Arg239His | C18: R239H | D18: C07 | E18: 50 | F18: 50 | G18: 23 | H18: 7 | I18: =G18/E18 -> 0.46 | J18: =F18/E18 -> 1 | L18: INFANTILE | M18: Cytoplasm | N18: Low | O18: Y | R18: Cytoplasm | S18: High | T18: Y | U18: Foci | W18: =IF(O18=T18, TRUE) -> TRUE | X18: INFANTILE
A19: C08 | B19: GFAP Asp295Asn | C19: D295N | D19: C08 | E19: 57 | F19: 3 | G19: 0 | H19: 4 | I19: =G19/E19 -> 0 | J19: =F19/E19 -> 0.052631579 | L19: INNOCUOUS | M19: IF | N19: Low | O19: N | R19: IF | S19: High | T19: N | W19: =IF(O19=T19, TRUE) -> TRUE | X19: INNOCUOUS
A20: C09 | B20: GFAP Ala364Pro | C20: A364P | D20: C09 | E20: 50 | F20: 19 | G20: 17 | H20: 25 | I20: =G20/E20 -> 0.34 | J20: =F20/E20 -> 0.38 | K20: weird different phenotype for perinnuclear aggregates | L20: INFANTILE | M20: Cytoplasm, IF | N20: Low | O20: Y | P20: Foci | R20: IF | S20: High | T20: Y | U20: Foci | V20: Transfection efficiency decent but expression level is low outside of foci | W20: =IF(O20=T20, TRUE) -> TRUE | X20: INFANTILE
A21: C10 | B21: GFAP Asn386Ile | C21: N386I | D21: C10 | E21: 66 | F21: 17 | G21: 14 | H21: 7 | I21: =G21/E21 -> 0.21212121 | J21: =F21/E21 -> 0.25757576 | L21: INFANTILE | M21: IF, Cytoplasm | N21: High | O21: Y | P21: Some Foci | R21: IF, Cytoplasm | S21: High | T21: Y | U21: Some Foci | W21: =IF(O21=T21, TRUE) -> TRUE | X21: INFANTILE
A22: C11 | B22: GFAP R416W | C22: R416W | D22: C11 | E22: not expressed | L22: MIXED | M22: IF | N22: Med | O22: N | R22: IF | S22: Low | T22: N | W22: =IF(O22=T22, TRUE) -> TRUE | X22: MIXED
A23: D02 | B23: GFAP Arg70Trp | C23: R70W | D23: D02 | E23: 52 | F23: 14 | G23: 6 | H23: 9 | I23: =G23/E23 -> 0.11538462 | J23: =F23/E23 -> 0.26923077 | L23: ADULT | M23: Not expressed | N23: NE | O23: NE | R23: IF | S23: High | T23: Y | U23: Foci | V23: Almost WT-like but ~5% cells have Foci too | X23: ADULT
A24: D03 | B24: GFAP Asn77Tyr | C24: N77Y | D24: D03 | E24: 53 | F24: 20 | G24: 19 | H24: 1 | I24: =G24/E24 -> 0.35849057 | J24: =F24/E24 -> 0.37735849 | L24: INFANTILE | M24: Cytoplasm, IF | N24: Med | O24: Y | P24: Foci | R24: Cytoplasm, IF | S24: High | T24: Y | U24: Foci | W24: =IF(O24=T24, TRUE) -> TRUE | X24: INFANTILE
A25: D04 | B25: GFAP Arg79His | C25: R79H | D25: D04 | L25: MOSTLY INFANTILE | M25: Not expressed | N25: NE | O25: NE | R25: Cytoplasm, IF | S25: High | T25: Y | U25: Foci | X25: MOSTLY INFANTILE
A26: D05 | B26: GFAP Leu90Pro | C26: L90P | D26: D05 | E26: 50 | F26: 50 | G26: 36 | H26: 0 | I26: =G26/E26 -> 0.72 | J26: =F26/E26 -> 1 | L26: INFANTILE | M26: Cytoplasm, IF | N26: Low | O26: Y | P26: Foci | R26: Cytoplasm, IF | S26: High | T26: Y | U26: Foci | W26: =IF(O26=T26, TRUE) -> TRUE | X26: INFANTILE
A27: D06 | B27: GFAP Glu207Lys | C27: E207K | D27: D06 | E27: 52 | F27: 28 | G27: 0 | H27: 16 | I27: =G27/E27 -> 0 | J27: =F27/E27 -> 0.53846154 | K27: perinuclear aggregation very. Large | L27: JUVENILE | M27: Not expressed | N27: NE | O27: NE | R27: IF | S27: High | T27: N | X27: JUVENILE
A28: D07 | B28: GFAP Arg239Pro | C28: R239P | D28: D07 | E28: 55 | F28: 32 | G28: 14 | H28: 1 | I28: =G28/E28 -> 0.25454545 | J28: =F28/E28 -> 0.58181818 | L28: MIXED | M28: Cytoplasm | N28: 2 cells | O28: Y | P28: Foci | R28: Cytoplasm, IF | S28: High | T28: Y | U28: Foci | W28: =IF(O28=T28, TRUE) -> TRUE | X28: MIXED
A29: D08 | B29: GFAP Leu331Pro | C29: L331P | D29: D08 | E29: 55 | F29: 8 | G29: 7 | H29: 0 | I29: =G29/E29 -> 0.12727273 | J29: =F29/E29 -> 0.14545455 | K29: expression level very low | L29: INFANTILE | M29: Cytoplasm | N29: 4 cells | O29: Y | P29: Foci | R29: IF | S29: Med | T29: Y | U29: Foci | V29: Transfection efficiency decent but expression level is low outside of foci | W29: =IF(O29=T29, TRUE) -> TRUE | X29: INFANTILE
A30: D09 | B30: GFAP Tyr366His | C30: Y366H | D30: D09 | E30: 53 | F30: 44 | G30: 21 | H30: 0 | I30: =G30/E30 -> 0.39622642 | J30: =F30/E30 -> 0.83018868 | L30: INFANTILE | M30: Cytoplasm | N30: Low | O30: Y | P30: Foci | R30: Cytoplasm | S30: High | T30: Y | U30: Foci | W30: =IF(O30=T30, TRUE) -> TRUE | X30: INFANTILE
A31: D10 | B31: GFAP Arg416Trp | C31: R416W | D31: D10 | E31: 66 | F31: 6 | G31: 6 | H31: 11 | I31: =G31/E31 -> 0.090909091 | J31: =F31/E31 -> 0.090909091 | L31: MIXED | M31: IF | N31: Low | O31: N | R31: IF | S31: High | T31: Y | U31: Foci | V31: Almost WT-like but ~5% cells have Foci too | W31: =IF(O31=T31, TRUE) -> FALSE | X31: MIXED
A32: D11 | B32: GFAP P47L | C32: P47L | D32: D11 | E32: 61 | F32: 9 | G32: 0 | H32: 5 | I32: =G32/E32 -> 0 | J32: =F32/E32 -> 0.14754098 | L32: Not in Severity list (Benign) | M32: IF | N32: Low | O32: N | R32: IF | S32: High | T32: N | W32: =IF(O32=T32, TRUE) -> TRUE | X32: Not in Severity list (Benign)
A33: E02 | B33: GFAP Arg70Gln | C33: R70Q | D33: E02 | E33: 51 | F33: 26 | G33: 30 | H33: 2 | I33: =G33/E33 -> 0.58823529 | J33: =F33/E33 -> 0.50980392 | L33: ADULT | M33: IF | N33: Low | O33: Y | P33: Foci | R33: IF, Cytoplasm | S33: High | T33: Y | U33: Foci | W33: =IF(O33=T33, TRUE) -> TRUE | X33: ADULT
A34: E03 | B34: GFAP Asn77Ser | C34: N77S | D34: E03 | E34: 63 | F34: 55 | G34: 22 | H34: 0 | I34: =G34/E34 -> 0.34920635 | J34: =F34/E34 -> 0.87301587 | L34: INFANTILE | M34: Cytoplasm, IF | N34: Low | O34: Y | P34: Some Foci | R34: Cytoplasm | S34: High | T34: Y | U34: Foci | W34: =IF(O34=T34, TRUE) -> TRUE | X34: INFANTILE
A35: E04 | B35: GFAP Arg79Leu | C35: R79L | D35: E04 | E35: 75 | F35: 41 | G35: 28 | H35: 0 | I35: =G35/E35 -> 0.37333333 | J35: =F35/E35 -> 0.54666667 | L35: INFANTILE | M35: Not expressed | N35: NE | O35: NE | Q35: Too few cells to make any call | R35: Cytoplasm, IF | S35: High | T35: Y | U35: Foci | X35: INFANTILE
A36: E05 | B36: GFAP Gln93Pro | C36: Q93P | D36: E05 | E36: 63 | F36: 56 | G36: 29 | H36: 0 | I36: =G36/E36 -> 0.46031746 | J36: =F36/E36 -> 0.88888889 | L36: JUVENILE | M36: Not expressed | N36: NE | O36: NE | Q36: Too few cells to make any call | R36: Cytoplasm | S36: High | T36: Y | U36: Foci | X36: JUVENILE
A37: E06 | B37: GFAP Glu210Lys | C37: E210K | D37: E06 | E37: 58 | F37: 15 | G37: 0 | H37: 14 | I37: =G37/E37 -> 0 | J37: =F37/E37 -> 0.25862069 | L37: MIXED | M37: IF | N37: Low | O37: N | R37: IF | S37: High | T37: Y | U37: Foci | V37: Almost WT-like but ~5% cells have Foci too | W37: =IF(O37=T37, TRUE) -> FALSE | X37: MIXED
A38: E07 | B38: GFAP Arg239Leu | C38: R239L | D38: E07 | E38: 59 | F38: 56 | G38: 24 | H38: 0 | I38: =G38/E38 -> 0.40677966 | J38: =F38/E38 -> 0.94915254 | L38: INFANTILE | M38: Cytoplasm | N38: Low | O38: Y | P38: Foci? | R38: Cytoplasm | S38: High | T38: Y | U38: Foci | W38: =IF(O38=T38, TRUE) -> TRUE | X38: INFANTILE
A39: E08 | B39: GFAP Leu352Pro | C39: L352P | D39: E08 | E39: 52 | F39: 16 | G39: 15 | H39: 20 | I39: =G39/E39 -> 0.28846154 | J39: =F39/E39 -> 0.30769231 | L39: INFANTILE | M39: Not expressed | N39: NE | O39: NE | Q39: Not enough cells to tell | R39: IF | S39: High | T39: Y | U39: Foci | V39: Transfection efficiency decent but expression level is low outside of foci | X39: INFANTILE
A40: E09 | B40: GFAP Glu371Gly | C40: E371G | D40: E09 | E40: 66 | F40: 54 | G40: 28 | H40: 0 | I40: =G40/E40 -> 0.42424242 | J40: =F40/E40 -> 0.81818182 | L40: INFANTILE | M40: Cytoplasm | N40: High | O40: Y | P40: Foci | R40: Cytoplasm | S40: High | T40: Y | U40: Foci | W40: =IF(O40=T40, TRUE) -> TRUE | X40: INFANTILE
...

Sheet Phenotypes
A1: Mutation | B1: Mutation | C1: Variant | D1: Well | E1: Class | F1: AOO information? | G1: AOO | H1: AAAO months | I1: AAAO years | J1: Reported as patient # | K1: Reference
A2: p.Lys 63 Gln | B2: Lys63Gln | C2: K63Q | D2: C02 | E2: =VLOOKUP(C2,Average!B$2:D$56,3,FALSE) -> Adult | F2: yes | G2: 21 | H2: =G2*12 -> 252 | I2: =H2/12 -> 21 | J2: 1 | K2: (Li et al., 2005)
A3: p.Arg 70 Gln | B3: Arg70Gln | C3: R70Q | D3: E02 | E3: =VLOOKUP(C3,Average!B$2:D$56,3,FALSE) -> Adult | F3: yes | G3: 39 | H3: =I3*12 -> 468 | I3: 39 | J3: 11 | K3: Graff-Radford et al. 2014
A4: p.Arg 70 Gln | B4: Arg70Gln | C4: R70Q | D4: E02 | E4: =VLOOKUP(C4,Average!B$2:D$56,3,FALSE) -> Adult | F4: yes | G4: 40.5 | H4: =I4*12 -> 486 | I4: 40.5 | J4: 12 | K4: (Caroli et al., 2007) and #1 in Jany et al. 2015
A5: p.Arg 105 Trp | B5: Arg105Trp | C5: R105W | D5: G05 | E5: =VLOOKUP(C5,Average!B$2:D$56,3,FALSE) -> benign/likely benign | F5: yes | G5: 6 | H5: =I5*12 -> 72 | I5: 6 | J5: 21, pathogenicity uncertain | K5: Jany et al. 2015
A6: p.Ala 253 Gly | B6: Ala253Gly | C6: A253G | D6: B08 | E6: =VLOOKUP(C6,Average!B$2:D$56,3,FALSE) -> Infantile | F6: yes | G6: 1 | H6: =G6*12 -> 12 | I6: 1 | J6: 30 | K6: (Li et al., 2005)
A7: p.Ala 364 Pro | B7: Ala364Pro | C7: A364P | D7: C09 | E7: =VLOOKUP(C7,Average!B$2:D$56,3,FALSE) -> Infantile | F7: yes | G7: 0 | H7: =G7*12 -> 0 | I7: =H7/12 -> 0 | J7: 35 | K7: (Li et al., 2005)
A8: p.Glu 373 Lys | B8: Glu373Lys | C8: E373K | D8: F09 | E8: =VLOOKUP(C8,Average!B$2:D$56,3,FALSE) -> Infantile | F8: yes | G8: 1.5m, 2m | H8: 1.75 | I8: 0.58333333 | J8: 37-38 | K8: (Li et al., 2005)
A9: p.Glu 373 Gln | B9: Glu373Gln | C9: E373Q | D9: G09 | E9: =VLOOKUP(C9,Average!B$2:D$56,3,FALSE) -> Infantile | F9: yes | G9: 3m | H9: 3 | I9: =H9/12 -> 0.25 | J9: 39 | K9: (Li et al., 2005)
A10: p.Glu 374 Gly | B10: Glu374Gly | C10: E374G | D10: G11 | E10: =VLOOKUP(C10,Average!B$2:D$56,3,FALSE) -> Infantile | F10: yes | G10: 1, 6m | H10: 9 | I10: =H10/12 -> 0.75 | J10: 40 | K10: (Li et al., 2005); #41 in Jany 2015
A11: p.Leu 76 Phe | B11: Leu76Phe | C11: L76F | D11: C03 | E11: =VLOOKUP(C11,Average!B$2:D$56,3,FALSE) -> Infantile | F11: yes | G11: 0.25m | H11: 0.25 | I11: =H11/12 -> 0.020833333 | J11: 3 | K11: (Li et al., 2005)
A12: p.Leu 76 Val | B12: Leu76Val | C12: L76V | D12: B03 | E12: =VLOOKUP(C12,Average!B$2:D$56,3,FALSE) -> Infantile | F12: yes | G12: 5m | H12: 5 | I12: =H12/12 -> 0.41666667 | J12: 4 | K12: (Li et al., 2005)
A13: p.Leu 97 Pro | B13: Leu97Pro | C13: L97P | D13: F05 | E13: =VLOOKUP(C13,Average!B$2:D$56,3,FALSE) -> Infantile | F13: yes | G13: 0 | H13: =G13*12 -> 0 | I13: =H13/12 -> 0 | J13: 10 | K13: (Li et al., 2005)
A14: p.Met 73 Thr | B14: Met73Thr | C14: M73T | D14: F02 | E14: =VLOOKUP(C14,Average!B$2:D$56,3,FALSE) -> Infantile | F14: yes | G14: 3m | H14: 3 | I14: =H14/12 -> 0.25 | J14: 2 | K14: (Li et al., 2005)
A15: p.Asn77 Ser | B15: Asn77Ser | C15: N77S | D15: E03 | E15: =VLOOKUP(C15,Average!B$2:D$56,3,FALSE) -> Infantile | F15: yes | G15: 0.16,1 | H15: =I15*12 -> 6.96 | I15: =AVERAGE(0.16,1) -> 0.58 | J15: 2-3 | K15: Jany et al. 2015
A16: p.Asn 77 Ser | B16: Asn77Ser | C16: N77S | D16: E03 | E16: =VLOOKUP(C16,Average!B$2:D$56,3,FALSE) -> Infantile | F16: yes | G16: 7m | H16: 7 | I16: =H16/12 -> 0.58333333 | J16: 5 | K16: (Li et al., 2005)
A17: p.Arg 239 His | B17: Arg239His | C17: R239H | D17: C07 | E17: =VLOOKUP(C17,Average!B$2:D$56,3,FALSE) -> Infantile | F17: yes | G17: 0.29, 0 | H17: =I17*12 -> 1.74 | I17: =AVERAGE(0.29, 0) -> 0.145 | J17: 30-31 | K17: Jany 2015
A18: p.Arg 239 His | B18: Arg239His | C18: R239H | D18: C07 | E18: =VLOOKUP(C18,Average!B$2:D$56,3,FALSE) -> Infantile | F18: yes | G18: 3m, 2m, 4m, 6m, 3m | H18: 3.6 | I18: =H18/12 -> 0.3 | J18: 23-27 | K18: (Li et al., 2005)
A19: p.Arg 258 Pro | B19: Arg258Pro | C19: R258P | D19: D11 | E19: =VLOOKUP(C19,Average!B$2:D$56,3,FALSE) -> Infantile | F19: yes | G19: 0 | H19: 0 | I19: 0 | J19: 35 | K19: Jany 2015
A20: p.Arg 79 Gly | B20: Arg79Gly | C20: R79G | D20: B04 | E20: =VLOOKUP(C20,Average!B$2:D$56,3,FALSE) -> Infantile | F20: yes | G20: 0.29 | H20: =G20*12 -> 3.48 | I20: =H20/12 -> 0.29 | J20: 9 | K20: Jany 2015
A21: p.Tyr 366 His | B21: Tyr366His | C21: Y366H | D21: D09 | E21: =VLOOKUP(C21,Average!B$2:D$56,3,FALSE) -> Infantile | F21: yes | G21: 1m | H21: 1 | I21: =H21/12 -> 0.083333333 | J21: 36 | K21: (Li et al., 2005)
A22: p.Glu 207 Lys | B22: Glu207Lys | C22: E207K | D22: D06 | E22: =VLOOKUP(C22,Average!B$2:D$56,3,FALSE) -> Juvenile | F22: yes | G22: 10 | H22: =G22*12 -> 120 | I22: =H22/12 -> 10 | J22: 11 | K22: (Li et al., 2005)
A23: p.Glu 207 Gln | B23: Glu207Gln | C23: E207Q | D23: F11 | E23: =VLOOKUP(C23,Average!B$2:D$56,3,FALSE) -> Juvenile | F23: yes | G23: 11 | H23: =G23*12 -> 132 | I23: =H23/12 -> 11 | J23: 12 | K23: (Li et al., 2005); #7 in van der Knaap 2005; #23 in Jany et al. 2015
A24: p.Leu 235 Pro | B24: Leu235Pro | C24: L235P | D24: G06 | E24: =VLOOKUP(C24,Average!B$2:D$56,3,FALSE) -> Juvenile | F24: yes | G24: 3 | H24: NA | I24: NA | J24: 14-15 twins | K24: (Li et al., 2005)
A25: p.Leu 235 Pro | B25: Leu235Pro | C25: L235P | D25: G06 | E25: =VLOOKUP(C25,Average!B$2:D$56,3,FALSE) -> Juvenile | F25: yes | G25: 2, 6m | H25: NA | I25: NA | J25: 16 | K25: (Li et al., 2005)
A26: p.Leu 359 Val | B26: Leu359Val | C26: L359V | D26: G08 | E26: =VLOOKUP(C26,Average!B$2:D$56,3,FALSE) -> Juvenile | F26: yes | G26: 3, 6m | H26: 4.5 | I26: =H26/12 -> 0.375 | J26: 34 | K26: (Li et al., 2005)
A27: p.Glu 210 Lys | B27: Glu210Lys | C27: E210K | D27: E06 | E27: =VLOOKUP(C27,Average!B$2:D$56,3,FALSE) -> Mixed | F27: yes | G27: 24 | H27: =G27*12 -> 288 | I27: =H27/12 -> 24 | J27: 13 | K27: (Li et al., 2005)
A28: p.Arg 239 Pro | B28: Arg239Pro | C28: R239P | D28: D07 | E28: =VLOOKUP(C28,Average!B$2:D$56,3,FALSE) -> Mixed | F28: yes | G28: 1.5 | H28: =I28*12 -> 18 | I28: 1.5 | J28: 33 | K28: Jany 2015
A29: p.Arg 239 Pro | B29: Arg239Pro | C29: R239P | D29: D07 | E29: =VLOOKUP(C29,Average!B$2:D$56,3,FALSE) -> Mixed | F29: yes | G29: 2 | H29: 24 | I29: 2 | K29: #28 in (Li et al., 2005); #1 in van der Knaap 2005; #32 in Jany 2015
A30: p.Arg 416 Trp | B30: Arg416Trp | C30: R416W | D30: D10 | E30: =VLOOKUP(C30,Average!B$2:D$56,3,FALSE) -> Mixed | F30: yes | G30: 10 | H30: =G30*12 -> 120 | I30: =H30/12 -> 10 | J30: 41 | K30: (Li et al., 2005)
A31: p.Arg 416 Trp | B31: Arg416Trp | C31: R416W | D31: D10 | E31: =VLOOKUP(C31,Average!B$2:D$56,3,FALSE) -> Mixed | F31: yes | G31: 13 | H31: =G31*12 -> 156 | I31: 13 | K31: #10 in (Caroli et al., 2007); #3 in Pareyson, 2008 and Farina 2008; # 47 in Jany 2015
A32: p.Arg 416 Trp | B32: Arg416Trp | C32: R416W | D32: D10 | E32: =VLOOKUP(C32,Average!B$2:D$56,3,FALSE) -> Mixed | F32: yes | G32: 14,6,16 | H32: =I32*12 -> 144 | I32: =AVERAGE(14,6,16) -> 12 | J32: 46, 48-49 | K32: Jany 2015
A33: p.Arg 88 Cys | B33: Arg88Cys | C33: R88C | D33: C05 | E33: =VLOOKUP(C33,Average!B$2:D$56,3,FALSE) -> Mixed | F33: yes | G33: 4 | H33: =G33*12 -> 48 | I33: 4 | J33: 9 & 10 | K33: (Gorospe et al., 2002) and #15 in Jany et al. 2015
A34: p.Arg 88 Cys | B34: Arg88Cys | C34: R88C | D34: C05 | E34: =VLOOKUP(C34,Average!B$2:D$56,3,FALSE) -> Mixed | F34: yes | G34: 6 | H34: =G34*12 -> 72 | I34: =H34/12 -> 6 | J34: 9 | K34: (Li et al., 2005)
A35: p.Arg 88 Cys | B35: Arg88Cys | C35: R88C | D35: C05 | E35: =VLOOKUP(C35,Average!B$2:D$56,3,FALSE) -> Mixed | F35: yes | G35: 0.75,2,10 | H35: =I35*12 -> 51 | I35: =AVERAGE(0.75,2,10) -> 4.25 | J35: 16-18 | K35: Jany 2015
A36: p.Arg 88 Cys | B36: Arg88Cys | C36: R88C | D36: C05 | E36: =VLOOKUP(C36,Average!B$2:D$56,3,FALSE) -> Mixed | F36: yes | G36: 10,10 | H36: =I36*12 -> 120 | I36: 10 | J36: 3,4 (mother-son pair), 7 | K36: (van der Knaap et. al., 2006) and #19-20 in Jany et al. 2015
A37: p.Arg 239 Cys | B37: Arg239Cys | C37: R239C | D37: B07 | E37: =VLOOKUP(C37,Average!B$2:D$56,3,FALSE) -> Mostly infantile | F37: yes | G37: 0.5, 1.5, 7, 1.67 | H37: =I37*12 -> 32.01 | I37: =AVERAGE(0.5, 1.5, 7, 1.67) -> 2.6675 | J37: 26-29 | K37: Jany 2015
A38: p.Arg 239 Cys | B38: Arg239Cys | C38: R239C | D38: B07 | E38: =VLOOKUP(C38,Average!B$2:D$56,3,FALSE) -> Mostly infantile | F38: yes | G38: 2, 1, 2m, 8m, 1y, 6m, 1m, 4y | H38: =I38*12 -> 11.6 | I38: =AVERAGE(2,1,2/12,8/12,1) -> 0.96666667 | J38: 17-22 | K38: (Li et al., 2005)
A39: p.Arg 79 Cys | B39: Arg79Cys | C39: R79C | D39: C04 | E39: =VLOOKUP(C39,Average!B$2:D$56,3,FALSE) -> Mostly infantile | F39: yes | G39: 4, 0.5 | H39: =I39*12 -> 27 | I39: =AVERAGE(4,0.5) -> 2.25 | J39: 7-8 | K39: Jany et al. 2015
A40: p.Arg 79 Cys | B40: Arg79Cys | C40: R79C | D40: C04 | E40: =VLOOKUP(C40,Average!B$2:D$56,3,FALSE) -> Mostly infantile | F40: yes | G40: 7,1,6m,7m | H40: =I40*12 -> 27.25 | I40: =AVERAGE(7,1,6/12,7/12) -> 2.2708333 | J40: 6-8 | K40: (Li et al., 2005) and #5 in Jany et al. 2015
...
